{
  "nbformat": 4,
  "nbformat_minor": 0,
  "metadata": {
    "colab": {
      "provenance": [],
      "authorship_tag": "ABX9TyOv9bKLqhdXdZAQb/+jjvbS",
      "include_colab_link": true
    },
    "kernelspec": {
      "name": "python3",
      "display_name": "Python 3"
    },
    "language_info": {
      "name": "python"
    }
  },
  "cells": [
    {
      "cell_type": "markdown",
      "metadata": {
        "id": "view-in-github",
        "colab_type": "text"
      },
      "source": [
        "<a href=\"https://colab.research.google.com/github/minhnhat232k/CS2205.CH1702_NguyenMinhNhat/blob/main/Assignment2_Bigdata_q5.ipynb\" target=\"_parent\"><img src=\"https://colab.research.google.com/assets/colab-badge.svg\" alt=\"Open In Colab\"/></a>"
      ]
    },
    {
      "cell_type": "code",
      "execution_count": 10,
      "metadata": {
        "colab": {
          "base_uri": "https://localhost:8080/"
        },
        "id": "iN6zoSS-dqTZ",
        "outputId": "7b8bed84-1568-40ec-bf4a-1d963b63cbec"
      },
      "outputs": [
        {
          "output_type": "stream",
          "name": "stdout",
          "text": [
            "Requirement already satisfied: pyspark==3.0.1 in /usr/local/lib/python3.6/site-packages (3.0.1)\n",
            "Requirement already satisfied: py4j==0.10.9 in /usr/local/lib/python3.6/site-packages (from pyspark==3.0.1) (0.10.9)\n",
            "\u001b[33mWARNING: Running pip as the 'root' user can result in broken permissions and conflicting behaviour with the system package manager. It is recommended to use a virtual environment instead: https://pip.pypa.io/warnings/venv\u001b[0m\n"
          ]
        }
      ],
      "source": [
        "!pip install pyspark==3.0.1"
      ]
    },
    {
      "cell_type": "code",
      "source": [
        "import pyspark\n",
        "from pyspark.sql import SparkSession\n",
        "from pyspark.sql import functions as f\n",
        "from pyspark.sql.types import IntegerType,BooleanType,DateType"
      ],
      "metadata": {
        "id": "dMN-Jg9hdrWV"
      },
      "execution_count": 11,
      "outputs": []
    },
    {
      "cell_type": "code",
      "source": [
        "from google.colab import drive\n",
        "drive.mount('/content/gdrive')\n",
        "spark = SparkSession.builder.getOrCreate()\n",
        "ratingsDF = spark.read.options(header='True', inferSchema='True', delimiter=',').csv(\"/content/gdrive/MyDrive/Bigdata-Pyspark-Dataset/Assignment2/ratings_small.csv\")\n",
        "moviesDF = spark.read.options(header='True', inferSchema='True', delimiter=',').csv(\"/content/gdrive/MyDrive/Bigdata-Pyspark-Dataset/Assignment2/movies_small.csv\")\n"
      ],
      "metadata": {
        "colab": {
          "base_uri": "https://localhost:8080/",
          "height": 1000
        },
        "id": "Lj4v_O2Cdsjr",
        "outputId": "35e71a7b-c3af-467f-ffca-f159aaf46baf"
      },
      "execution_count": 13,
      "outputs": [
        {
          "output_type": "stream",
          "name": "stderr",
          "text": [
            "ERROR:py4j.java_gateway:An error occurred while trying to connect to the Java server (127.0.0.1:42473)\n",
            "Traceback (most recent call last):\n",
            "  File \"/usr/local/lib/python3.10/dist-packages/py4j/java_gateway.py\", line 977, in _get_connection\n",
            "    connection = self.deque.pop()\n",
            "IndexError: pop from an empty deque\n",
            "\n",
            "During handling of the above exception, another exception occurred:\n",
            "\n",
            "Traceback (most recent call last):\n",
            "  File \"/usr/local/lib/python3.10/dist-packages/py4j/java_gateway.py\", line 1115, in start\n",
            "    self.socket.connect((self.address, self.port))\n",
            "ConnectionRefusedError: [Errno 111] Connection refused\n",
            "ERROR:py4j.java_gateway:An error occurred while trying to connect to the Java server (127.0.0.1:42473)\n",
            "Traceback (most recent call last):\n",
            "  File \"/usr/local/lib/python3.10/dist-packages/py4j/java_gateway.py\", line 977, in _get_connection\n",
            "    connection = self.deque.pop()\n",
            "IndexError: pop from an empty deque\n",
            "\n",
            "During handling of the above exception, another exception occurred:\n",
            "\n",
            "Traceback (most recent call last):\n",
            "  File \"/usr/local/lib/python3.10/dist-packages/py4j/java_gateway.py\", line 1115, in start\n",
            "    self.socket.connect((self.address, self.port))\n",
            "ConnectionRefusedError: [Errno 111] Connection refused\n",
            "ERROR:py4j.java_gateway:An error occurred while trying to connect to the Java server (127.0.0.1:42473)\n",
            "Traceback (most recent call last):\n",
            "  File \"/usr/local/lib/python3.10/dist-packages/py4j/java_gateway.py\", line 977, in _get_connection\n",
            "    connection = self.deque.pop()\n",
            "IndexError: pop from an empty deque\n",
            "\n",
            "During handling of the above exception, another exception occurred:\n",
            "\n",
            "Traceback (most recent call last):\n",
            "  File \"/usr/local/lib/python3.10/dist-packages/py4j/java_gateway.py\", line 1115, in start\n",
            "    self.socket.connect((self.address, self.port))\n",
            "ConnectionRefusedError: [Errno 111] Connection refused\n",
            "ERROR:py4j.java_gateway:An error occurred while trying to connect to the Java server (127.0.0.1:42473)\n",
            "Traceback (most recent call last):\n",
            "  File \"/usr/local/lib/python3.10/dist-packages/py4j/java_gateway.py\", line 977, in _get_connection\n",
            "    connection = self.deque.pop()\n",
            "IndexError: pop from an empty deque\n",
            "\n",
            "During handling of the above exception, another exception occurred:\n",
            "\n",
            "Traceback (most recent call last):\n",
            "  File \"/usr/local/lib/python3.10/dist-packages/py4j/java_gateway.py\", line 1115, in start\n",
            "    self.socket.connect((self.address, self.port))\n",
            "ConnectionRefusedError: [Errno 111] Connection refused\n",
            "ERROR:py4j.java_gateway:An error occurred while trying to connect to the Java server (127.0.0.1:42473)\n",
            "Traceback (most recent call last):\n",
            "  File \"/usr/local/lib/python3.10/dist-packages/py4j/java_gateway.py\", line 977, in _get_connection\n",
            "    connection = self.deque.pop()\n",
            "IndexError: pop from an empty deque\n",
            "\n",
            "During handling of the above exception, another exception occurred:\n",
            "\n",
            "Traceback (most recent call last):\n",
            "  File \"/usr/local/lib/python3.10/dist-packages/py4j/java_gateway.py\", line 1115, in start\n",
            "    self.socket.connect((self.address, self.port))\n",
            "ConnectionRefusedError: [Errno 111] Connection refused\n",
            "ERROR:py4j.java_gateway:An error occurred while trying to connect to the Java server (127.0.0.1:42473)\n",
            "Traceback (most recent call last):\n",
            "  File \"/usr/local/lib/python3.10/dist-packages/py4j/java_gateway.py\", line 977, in _get_connection\n",
            "    connection = self.deque.pop()\n",
            "IndexError: pop from an empty deque\n",
            "\n",
            "During handling of the above exception, another exception occurred:\n",
            "\n",
            "Traceback (most recent call last):\n",
            "  File \"/usr/local/lib/python3.10/dist-packages/py4j/java_gateway.py\", line 1115, in start\n",
            "    self.socket.connect((self.address, self.port))\n",
            "ConnectionRefusedError: [Errno 111] Connection refused\n",
            "ERROR:py4j.java_gateway:An error occurred while trying to connect to the Java server (127.0.0.1:42473)\n",
            "Traceback (most recent call last):\n",
            "  File \"/usr/local/lib/python3.10/dist-packages/py4j/java_gateway.py\", line 977, in _get_connection\n",
            "    connection = self.deque.pop()\n",
            "IndexError: pop from an empty deque\n",
            "\n",
            "During handling of the above exception, another exception occurred:\n",
            "\n",
            "Traceback (most recent call last):\n",
            "  File \"/usr/local/lib/python3.10/dist-packages/py4j/java_gateway.py\", line 1115, in start\n",
            "    self.socket.connect((self.address, self.port))\n",
            "ConnectionRefusedError: [Errno 111] Connection refused\n",
            "ERROR:py4j.java_gateway:An error occurred while trying to connect to the Java server (127.0.0.1:42473)\n",
            "Traceback (most recent call last):\n",
            "  File \"/usr/local/lib/python3.10/dist-packages/py4j/java_gateway.py\", line 977, in _get_connection\n",
            "    connection = self.deque.pop()\n",
            "IndexError: pop from an empty deque\n",
            "\n",
            "During handling of the above exception, another exception occurred:\n",
            "\n",
            "Traceback (most recent call last):\n",
            "  File \"/usr/local/lib/python3.10/dist-packages/py4j/java_gateway.py\", line 1115, in start\n",
            "    self.socket.connect((self.address, self.port))\n",
            "ConnectionRefusedError: [Errno 111] Connection refused\n",
            "ERROR:py4j.java_gateway:An error occurred while trying to connect to the Java server (127.0.0.1:42473)\n",
            "Traceback (most recent call last):\n",
            "  File \"/usr/local/lib/python3.10/dist-packages/py4j/java_gateway.py\", line 977, in _get_connection\n",
            "    connection = self.deque.pop()\n",
            "IndexError: pop from an empty deque\n",
            "\n",
            "During handling of the above exception, another exception occurred:\n",
            "\n",
            "Traceback (most recent call last):\n",
            "  File \"/usr/local/lib/python3.10/dist-packages/py4j/java_gateway.py\", line 1115, in start\n",
            "    self.socket.connect((self.address, self.port))\n",
            "ConnectionRefusedError: [Errno 111] Connection refused\n",
            "ERROR:py4j.java_gateway:An error occurred while trying to connect to the Java server (127.0.0.1:42473)\n",
            "Traceback (most recent call last):\n",
            "  File \"/usr/local/lib/python3.10/dist-packages/py4j/java_gateway.py\", line 977, in _get_connection\n",
            "    connection = self.deque.pop()\n",
            "IndexError: pop from an empty deque\n",
            "\n",
            "During handling of the above exception, another exception occurred:\n",
            "\n",
            "Traceback (most recent call last):\n",
            "  File \"/usr/local/lib/python3.10/dist-packages/py4j/java_gateway.py\", line 1115, in start\n",
            "    self.socket.connect((self.address, self.port))\n",
            "ConnectionRefusedError: [Errno 111] Connection refused\n",
            "ERROR:py4j.java_gateway:An error occurred while trying to connect to the Java server (127.0.0.1:42473)\n",
            "Traceback (most recent call last):\n",
            "  File \"/usr/local/lib/python3.10/dist-packages/py4j/java_gateway.py\", line 977, in _get_connection\n",
            "    connection = self.deque.pop()\n",
            "IndexError: pop from an empty deque\n",
            "\n",
            "During handling of the above exception, another exception occurred:\n",
            "\n",
            "Traceback (most recent call last):\n",
            "  File \"/usr/local/lib/python3.10/dist-packages/py4j/java_gateway.py\", line 1115, in start\n",
            "    self.socket.connect((self.address, self.port))\n",
            "ConnectionRefusedError: [Errno 111] Connection refused\n",
            "ERROR:py4j.java_gateway:An error occurred while trying to connect to the Java server (127.0.0.1:42473)\n",
            "Traceback (most recent call last):\n",
            "  File \"/usr/local/lib/python3.10/dist-packages/py4j/java_gateway.py\", line 977, in _get_connection\n",
            "    connection = self.deque.pop()\n",
            "IndexError: pop from an empty deque\n",
            "\n",
            "During handling of the above exception, another exception occurred:\n",
            "\n",
            "Traceback (most recent call last):\n",
            "  File \"/usr/local/lib/python3.10/dist-packages/py4j/java_gateway.py\", line 1115, in start\n",
            "    self.socket.connect((self.address, self.port))\n",
            "ConnectionRefusedError: [Errno 111] Connection refused\n",
            "ERROR:py4j.java_gateway:An error occurred while trying to connect to the Java server (127.0.0.1:42473)\n",
            "Traceback (most recent call last):\n",
            "  File \"/usr/local/lib/python3.10/dist-packages/py4j/java_gateway.py\", line 977, in _get_connection\n",
            "    connection = self.deque.pop()\n",
            "IndexError: pop from an empty deque\n",
            "\n",
            "During handling of the above exception, another exception occurred:\n",
            "\n",
            "Traceback (most recent call last):\n",
            "  File \"/usr/local/lib/python3.10/dist-packages/py4j/java_gateway.py\", line 1115, in start\n",
            "    self.socket.connect((self.address, self.port))\n",
            "ConnectionRefusedError: [Errno 111] Connection refused\n",
            "ERROR:py4j.java_gateway:An error occurred while trying to connect to the Java server (127.0.0.1:42473)\n",
            "Traceback (most recent call last):\n",
            "  File \"/usr/local/lib/python3.10/dist-packages/py4j/java_gateway.py\", line 977, in _get_connection\n",
            "    connection = self.deque.pop()\n",
            "IndexError: pop from an empty deque\n",
            "\n",
            "During handling of the above exception, another exception occurred:\n",
            "\n",
            "Traceback (most recent call last):\n",
            "  File \"/usr/local/lib/python3.10/dist-packages/py4j/java_gateway.py\", line 1115, in start\n",
            "    self.socket.connect((self.address, self.port))\n",
            "ConnectionRefusedError: [Errno 111] Connection refused\n",
            "ERROR:py4j.java_gateway:An error occurred while trying to connect to the Java server (127.0.0.1:42473)\n",
            "Traceback (most recent call last):\n",
            "  File \"/usr/local/lib/python3.10/dist-packages/py4j/java_gateway.py\", line 977, in _get_connection\n",
            "    connection = self.deque.pop()\n",
            "IndexError: pop from an empty deque\n",
            "\n",
            "During handling of the above exception, another exception occurred:\n",
            "\n",
            "Traceback (most recent call last):\n",
            "  File \"/usr/local/lib/python3.10/dist-packages/py4j/java_gateway.py\", line 1115, in start\n",
            "    self.socket.connect((self.address, self.port))\n",
            "ConnectionRefusedError: [Errno 111] Connection refused\n",
            "ERROR:py4j.java_gateway:An error occurred while trying to connect to the Java server (127.0.0.1:42473)\n",
            "Traceback (most recent call last):\n",
            "  File \"/usr/local/lib/python3.10/dist-packages/py4j/java_gateway.py\", line 977, in _get_connection\n",
            "    connection = self.deque.pop()\n",
            "IndexError: pop from an empty deque\n",
            "\n",
            "During handling of the above exception, another exception occurred:\n",
            "\n",
            "Traceback (most recent call last):\n",
            "  File \"/usr/local/lib/python3.10/dist-packages/py4j/java_gateway.py\", line 1115, in start\n",
            "    self.socket.connect((self.address, self.port))\n",
            "ConnectionRefusedError: [Errno 111] Connection refused\n",
            "ERROR:py4j.java_gateway:An error occurred while trying to connect to the Java server (127.0.0.1:42473)\n",
            "Traceback (most recent call last):\n",
            "  File \"/usr/local/lib/python3.10/dist-packages/py4j/java_gateway.py\", line 977, in _get_connection\n",
            "    connection = self.deque.pop()\n",
            "IndexError: pop from an empty deque\n",
            "\n",
            "During handling of the above exception, another exception occurred:\n",
            "\n",
            "Traceback (most recent call last):\n",
            "  File \"/usr/local/lib/python3.10/dist-packages/py4j/java_gateway.py\", line 1115, in start\n",
            "    self.socket.connect((self.address, self.port))\n",
            "ConnectionRefusedError: [Errno 111] Connection refused\n",
            "ERROR:py4j.java_gateway:An error occurred while trying to connect to the Java server (127.0.0.1:42473)\n",
            "Traceback (most recent call last):\n",
            "  File \"/usr/local/lib/python3.10/dist-packages/py4j/java_gateway.py\", line 977, in _get_connection\n",
            "    connection = self.deque.pop()\n",
            "IndexError: pop from an empty deque\n",
            "\n",
            "During handling of the above exception, another exception occurred:\n",
            "\n",
            "Traceback (most recent call last):\n",
            "  File \"/usr/local/lib/python3.10/dist-packages/py4j/java_gateway.py\", line 1115, in start\n",
            "    self.socket.connect((self.address, self.port))\n",
            "ConnectionRefusedError: [Errno 111] Connection refused\n",
            "ERROR:py4j.java_gateway:An error occurred while trying to connect to the Java server (127.0.0.1:42473)\n",
            "Traceback (most recent call last):\n",
            "  File \"/usr/local/lib/python3.10/dist-packages/py4j/java_gateway.py\", line 977, in _get_connection\n",
            "    connection = self.deque.pop()\n",
            "IndexError: pop from an empty deque\n",
            "\n",
            "During handling of the above exception, another exception occurred:\n",
            "\n",
            "Traceback (most recent call last):\n",
            "  File \"/usr/local/lib/python3.10/dist-packages/py4j/java_gateway.py\", line 1115, in start\n",
            "    self.socket.connect((self.address, self.port))\n",
            "ConnectionRefusedError: [Errno 111] Connection refused\n",
            "ERROR:py4j.java_gateway:An error occurred while trying to connect to the Java server (127.0.0.1:42473)\n",
            "Traceback (most recent call last):\n",
            "  File \"/usr/local/lib/python3.10/dist-packages/py4j/java_gateway.py\", line 977, in _get_connection\n",
            "    connection = self.deque.pop()\n",
            "IndexError: pop from an empty deque\n",
            "\n",
            "During handling of the above exception, another exception occurred:\n",
            "\n",
            "Traceback (most recent call last):\n",
            "  File \"/usr/local/lib/python3.10/dist-packages/py4j/java_gateway.py\", line 1115, in start\n",
            "    self.socket.connect((self.address, self.port))\n",
            "ConnectionRefusedError: [Errno 111] Connection refused\n",
            "ERROR:py4j.java_gateway:An error occurred while trying to connect to the Java server (127.0.0.1:42473)\n",
            "Traceback (most recent call last):\n",
            "  File \"/usr/local/lib/python3.10/dist-packages/py4j/java_gateway.py\", line 977, in _get_connection\n",
            "    connection = self.deque.pop()\n",
            "IndexError: pop from an empty deque\n",
            "\n",
            "During handling of the above exception, another exception occurred:\n",
            "\n",
            "Traceback (most recent call last):\n",
            "  File \"/usr/local/lib/python3.10/dist-packages/py4j/java_gateway.py\", line 1115, in start\n",
            "    self.socket.connect((self.address, self.port))\n",
            "ConnectionRefusedError: [Errno 111] Connection refused\n",
            "ERROR:py4j.java_gateway:An error occurred while trying to connect to the Java server (127.0.0.1:42473)\n",
            "Traceback (most recent call last):\n",
            "  File \"/usr/local/lib/python3.10/dist-packages/py4j/java_gateway.py\", line 977, in _get_connection\n",
            "    connection = self.deque.pop()\n",
            "IndexError: pop from an empty deque\n",
            "\n",
            "During handling of the above exception, another exception occurred:\n",
            "\n",
            "Traceback (most recent call last):\n",
            "  File \"/usr/local/lib/python3.10/dist-packages/py4j/java_gateway.py\", line 1115, in start\n",
            "    self.socket.connect((self.address, self.port))\n",
            "ConnectionRefusedError: [Errno 111] Connection refused\n",
            "ERROR:py4j.java_gateway:An error occurred while trying to connect to the Java server (127.0.0.1:42473)\n",
            "Traceback (most recent call last):\n",
            "  File \"/usr/local/lib/python3.10/dist-packages/py4j/java_gateway.py\", line 977, in _get_connection\n",
            "    connection = self.deque.pop()\n",
            "IndexError: pop from an empty deque\n",
            "\n",
            "During handling of the above exception, another exception occurred:\n",
            "\n",
            "Traceback (most recent call last):\n",
            "  File \"/usr/local/lib/python3.10/dist-packages/py4j/java_gateway.py\", line 1115, in start\n",
            "    self.socket.connect((self.address, self.port))\n",
            "ConnectionRefusedError: [Errno 111] Connection refused\n",
            "ERROR:py4j.java_gateway:An error occurred while trying to connect to the Java server (127.0.0.1:42473)\n",
            "Traceback (most recent call last):\n",
            "  File \"/usr/local/lib/python3.10/dist-packages/py4j/java_gateway.py\", line 977, in _get_connection\n",
            "    connection = self.deque.pop()\n",
            "IndexError: pop from an empty deque\n",
            "\n",
            "During handling of the above exception, another exception occurred:\n",
            "\n",
            "Traceback (most recent call last):\n",
            "  File \"/usr/local/lib/python3.10/dist-packages/py4j/java_gateway.py\", line 1115, in start\n",
            "    self.socket.connect((self.address, self.port))\n",
            "ConnectionRefusedError: [Errno 111] Connection refused\n",
            "ERROR:py4j.java_gateway:An error occurred while trying to connect to the Java server (127.0.0.1:42473)\n",
            "Traceback (most recent call last):\n",
            "  File \"/usr/local/lib/python3.10/dist-packages/py4j/java_gateway.py\", line 977, in _get_connection\n",
            "    connection = self.deque.pop()\n",
            "IndexError: pop from an empty deque\n",
            "\n",
            "During handling of the above exception, another exception occurred:\n",
            "\n",
            "Traceback (most recent call last):\n",
            "  File \"/usr/local/lib/python3.10/dist-packages/py4j/java_gateway.py\", line 1115, in start\n",
            "    self.socket.connect((self.address, self.port))\n",
            "ConnectionRefusedError: [Errno 111] Connection refused\n",
            "ERROR:py4j.java_gateway:An error occurred while trying to connect to the Java server (127.0.0.1:42473)\n",
            "Traceback (most recent call last):\n",
            "  File \"/usr/local/lib/python3.10/dist-packages/py4j/java_gateway.py\", line 977, in _get_connection\n",
            "    connection = self.deque.pop()\n",
            "IndexError: pop from an empty deque\n",
            "\n",
            "During handling of the above exception, another exception occurred:\n",
            "\n",
            "Traceback (most recent call last):\n",
            "  File \"/usr/local/lib/python3.10/dist-packages/py4j/java_gateway.py\", line 1115, in start\n",
            "    self.socket.connect((self.address, self.port))\n",
            "ConnectionRefusedError: [Errno 111] Connection refused\n",
            "ERROR:py4j.java_gateway:An error occurred while trying to connect to the Java server (127.0.0.1:42473)\n",
            "Traceback (most recent call last):\n",
            "  File \"/usr/local/lib/python3.10/dist-packages/py4j/java_gateway.py\", line 977, in _get_connection\n",
            "    connection = self.deque.pop()\n",
            "IndexError: pop from an empty deque\n",
            "\n",
            "During handling of the above exception, another exception occurred:\n",
            "\n",
            "Traceback (most recent call last):\n",
            "  File \"/usr/local/lib/python3.10/dist-packages/py4j/java_gateway.py\", line 1115, in start\n",
            "    self.socket.connect((self.address, self.port))\n",
            "ConnectionRefusedError: [Errno 111] Connection refused\n",
            "ERROR:py4j.java_gateway:An error occurred while trying to connect to the Java server (127.0.0.1:42473)\n",
            "Traceback (most recent call last):\n",
            "  File \"/usr/local/lib/python3.10/dist-packages/py4j/java_gateway.py\", line 977, in _get_connection\n",
            "    connection = self.deque.pop()\n",
            "IndexError: pop from an empty deque\n",
            "\n",
            "During handling of the above exception, another exception occurred:\n",
            "\n",
            "Traceback (most recent call last):\n",
            "  File \"/usr/local/lib/python3.10/dist-packages/py4j/java_gateway.py\", line 1115, in start\n",
            "    self.socket.connect((self.address, self.port))\n",
            "ConnectionRefusedError: [Errno 111] Connection refused\n",
            "ERROR:py4j.java_gateway:An error occurred while trying to connect to the Java server (127.0.0.1:42473)\n",
            "Traceback (most recent call last):\n",
            "  File \"/usr/local/lib/python3.10/dist-packages/py4j/java_gateway.py\", line 977, in _get_connection\n",
            "    connection = self.deque.pop()\n",
            "IndexError: pop from an empty deque\n",
            "\n",
            "During handling of the above exception, another exception occurred:\n",
            "\n",
            "Traceback (most recent call last):\n",
            "  File \"/usr/local/lib/python3.10/dist-packages/py4j/java_gateway.py\", line 1115, in start\n",
            "    self.socket.connect((self.address, self.port))\n",
            "ConnectionRefusedError: [Errno 111] Connection refused\n",
            "ERROR:py4j.java_gateway:An error occurred while trying to connect to the Java server (127.0.0.1:42473)\n",
            "Traceback (most recent call last):\n",
            "  File \"/usr/local/lib/python3.10/dist-packages/py4j/java_gateway.py\", line 977, in _get_connection\n",
            "    connection = self.deque.pop()\n",
            "IndexError: pop from an empty deque\n",
            "\n",
            "During handling of the above exception, another exception occurred:\n",
            "\n",
            "Traceback (most recent call last):\n",
            "  File \"/usr/local/lib/python3.10/dist-packages/py4j/java_gateway.py\", line 1115, in start\n",
            "    self.socket.connect((self.address, self.port))\n",
            "ConnectionRefusedError: [Errno 111] Connection refused\n",
            "ERROR:py4j.java_gateway:An error occurred while trying to connect to the Java server (127.0.0.1:42473)\n",
            "Traceback (most recent call last):\n",
            "  File \"/usr/local/lib/python3.10/dist-packages/py4j/java_gateway.py\", line 977, in _get_connection\n",
            "    connection = self.deque.pop()\n",
            "IndexError: pop from an empty deque\n",
            "\n",
            "During handling of the above exception, another exception occurred:\n",
            "\n",
            "Traceback (most recent call last):\n",
            "  File \"/usr/local/lib/python3.10/dist-packages/py4j/java_gateway.py\", line 1115, in start\n",
            "    self.socket.connect((self.address, self.port))\n",
            "ConnectionRefusedError: [Errno 111] Connection refused\n",
            "ERROR:py4j.java_gateway:An error occurred while trying to connect to the Java server (127.0.0.1:42473)\n",
            "Traceback (most recent call last):\n",
            "  File \"/usr/local/lib/python3.10/dist-packages/py4j/java_gateway.py\", line 977, in _get_connection\n",
            "    connection = self.deque.pop()\n",
            "IndexError: pop from an empty deque\n",
            "\n",
            "During handling of the above exception, another exception occurred:\n",
            "\n",
            "Traceback (most recent call last):\n",
            "  File \"/usr/local/lib/python3.10/dist-packages/py4j/java_gateway.py\", line 1115, in start\n",
            "    self.socket.connect((self.address, self.port))\n",
            "ConnectionRefusedError: [Errno 111] Connection refused\n",
            "ERROR:py4j.java_gateway:An error occurred while trying to connect to the Java server (127.0.0.1:42473)\n",
            "Traceback (most recent call last):\n",
            "  File \"/usr/local/lib/python3.10/dist-packages/py4j/java_gateway.py\", line 977, in _get_connection\n",
            "    connection = self.deque.pop()\n",
            "IndexError: pop from an empty deque\n",
            "\n",
            "During handling of the above exception, another exception occurred:\n",
            "\n",
            "Traceback (most recent call last):\n",
            "  File \"/usr/local/lib/python3.10/dist-packages/py4j/java_gateway.py\", line 1115, in start\n",
            "    self.socket.connect((self.address, self.port))\n",
            "ConnectionRefusedError: [Errno 111] Connection refused\n",
            "ERROR:py4j.java_gateway:An error occurred while trying to connect to the Java server (127.0.0.1:42473)\n",
            "Traceback (most recent call last):\n",
            "  File \"/usr/local/lib/python3.10/dist-packages/py4j/java_gateway.py\", line 977, in _get_connection\n",
            "    connection = self.deque.pop()\n",
            "IndexError: pop from an empty deque\n",
            "\n",
            "During handling of the above exception, another exception occurred:\n",
            "\n",
            "Traceback (most recent call last):\n",
            "  File \"/usr/local/lib/python3.10/dist-packages/py4j/java_gateway.py\", line 1115, in start\n",
            "    self.socket.connect((self.address, self.port))\n",
            "ConnectionRefusedError: [Errno 111] Connection refused\n",
            "ERROR:py4j.java_gateway:An error occurred while trying to connect to the Java server (127.0.0.1:42473)\n",
            "Traceback (most recent call last):\n",
            "  File \"/usr/local/lib/python3.10/dist-packages/py4j/java_gateway.py\", line 977, in _get_connection\n",
            "    connection = self.deque.pop()\n",
            "IndexError: pop from an empty deque\n",
            "\n",
            "During handling of the above exception, another exception occurred:\n",
            "\n",
            "Traceback (most recent call last):\n",
            "  File \"/usr/local/lib/python3.10/dist-packages/py4j/java_gateway.py\", line 1115, in start\n",
            "    self.socket.connect((self.address, self.port))\n",
            "ConnectionRefusedError: [Errno 111] Connection refused\n",
            "ERROR:py4j.java_gateway:An error occurred while trying to connect to the Java server (127.0.0.1:42473)\n",
            "Traceback (most recent call last):\n",
            "  File \"/usr/local/lib/python3.10/dist-packages/py4j/java_gateway.py\", line 977, in _get_connection\n",
            "    connection = self.deque.pop()\n",
            "IndexError: pop from an empty deque\n",
            "\n",
            "During handling of the above exception, another exception occurred:\n",
            "\n",
            "Traceback (most recent call last):\n",
            "  File \"/usr/local/lib/python3.10/dist-packages/py4j/java_gateway.py\", line 1115, in start\n",
            "    self.socket.connect((self.address, self.port))\n",
            "ConnectionRefusedError: [Errno 111] Connection refused\n",
            "ERROR:py4j.java_gateway:An error occurred while trying to connect to the Java server (127.0.0.1:42473)\n",
            "Traceback (most recent call last):\n",
            "  File \"/usr/local/lib/python3.10/dist-packages/py4j/java_gateway.py\", line 977, in _get_connection\n",
            "    connection = self.deque.pop()\n",
            "IndexError: pop from an empty deque\n",
            "\n",
            "During handling of the above exception, another exception occurred:\n",
            "\n",
            "Traceback (most recent call last):\n",
            "  File \"/usr/local/lib/python3.10/dist-packages/py4j/java_gateway.py\", line 1115, in start\n",
            "    self.socket.connect((self.address, self.port))\n",
            "ConnectionRefusedError: [Errno 111] Connection refused\n"
          ]
        },
        {
          "output_type": "stream",
          "name": "stdout",
          "text": [
            "Drive already mounted at /content/gdrive; to attempt to forcibly remount, call drive.mount(\"/content/gdrive\", force_remount=True).\n"
          ]
        },
        {
          "output_type": "error",
          "ename": "Py4JNetworkError",
          "evalue": "ignored",
          "traceback": [
            "\u001b[0;31m---------------------------------------------------------------------------\u001b[0m",
            "\u001b[0;31mIndexError\u001b[0m                                Traceback (most recent call last)",
            "\u001b[0;32m/usr/local/lib/python3.10/dist-packages/py4j/java_gateway.py\u001b[0m in \u001b[0;36m_get_connection\u001b[0;34m(self)\u001b[0m\n\u001b[1;32m    976\u001b[0m         \u001b[0;32mtry\u001b[0m\u001b[0;34m:\u001b[0m\u001b[0;34m\u001b[0m\u001b[0;34m\u001b[0m\u001b[0m\n\u001b[0;32m--> 977\u001b[0;31m             \u001b[0mconnection\u001b[0m \u001b[0;34m=\u001b[0m \u001b[0mself\u001b[0m\u001b[0;34m.\u001b[0m\u001b[0mdeque\u001b[0m\u001b[0;34m.\u001b[0m\u001b[0mpop\u001b[0m\u001b[0;34m(\u001b[0m\u001b[0;34m)\u001b[0m\u001b[0;34m\u001b[0m\u001b[0;34m\u001b[0m\u001b[0m\n\u001b[0m\u001b[1;32m    978\u001b[0m         \u001b[0;32mexcept\u001b[0m \u001b[0mIndexError\u001b[0m\u001b[0;34m:\u001b[0m\u001b[0;34m\u001b[0m\u001b[0;34m\u001b[0m\u001b[0m\n",
            "\u001b[0;31mIndexError\u001b[0m: pop from an empty deque",
            "\nDuring handling of the above exception, another exception occurred:\n",
            "\u001b[0;31mConnectionRefusedError\u001b[0m                    Traceback (most recent call last)",
            "\u001b[0;32m/usr/local/lib/python3.10/dist-packages/py4j/java_gateway.py\u001b[0m in \u001b[0;36mstart\u001b[0;34m(self)\u001b[0m\n\u001b[1;32m   1114\u001b[0m         \u001b[0;32mtry\u001b[0m\u001b[0;34m:\u001b[0m\u001b[0;34m\u001b[0m\u001b[0;34m\u001b[0m\u001b[0m\n\u001b[0;32m-> 1115\u001b[0;31m             \u001b[0mself\u001b[0m\u001b[0;34m.\u001b[0m\u001b[0msocket\u001b[0m\u001b[0;34m.\u001b[0m\u001b[0mconnect\u001b[0m\u001b[0;34m(\u001b[0m\u001b[0;34m(\u001b[0m\u001b[0mself\u001b[0m\u001b[0;34m.\u001b[0m\u001b[0maddress\u001b[0m\u001b[0;34m,\u001b[0m \u001b[0mself\u001b[0m\u001b[0;34m.\u001b[0m\u001b[0mport\u001b[0m\u001b[0;34m)\u001b[0m\u001b[0;34m)\u001b[0m\u001b[0;34m\u001b[0m\u001b[0;34m\u001b[0m\u001b[0m\n\u001b[0m\u001b[1;32m   1116\u001b[0m             \u001b[0mself\u001b[0m\u001b[0;34m.\u001b[0m\u001b[0mstream\u001b[0m \u001b[0;34m=\u001b[0m \u001b[0mself\u001b[0m\u001b[0;34m.\u001b[0m\u001b[0msocket\u001b[0m\u001b[0;34m.\u001b[0m\u001b[0mmakefile\u001b[0m\u001b[0;34m(\u001b[0m\u001b[0;34m\"rb\"\u001b[0m\u001b[0;34m)\u001b[0m\u001b[0;34m\u001b[0m\u001b[0;34m\u001b[0m\u001b[0m\n",
            "\u001b[0;31mConnectionRefusedError\u001b[0m: [Errno 111] Connection refused",
            "\nDuring handling of the above exception, another exception occurred:\n",
            "\u001b[0;31mPy4JNetworkError\u001b[0m                          Traceback (most recent call last)",
            "\u001b[0;32m<ipython-input-13-50301c9c080e>\u001b[0m in \u001b[0;36m<cell line: 4>\u001b[0;34m()\u001b[0m\n\u001b[1;32m      2\u001b[0m \u001b[0mdrive\u001b[0m\u001b[0;34m.\u001b[0m\u001b[0mmount\u001b[0m\u001b[0;34m(\u001b[0m\u001b[0;34m'/content/gdrive'\u001b[0m\u001b[0;34m)\u001b[0m\u001b[0;34m\u001b[0m\u001b[0;34m\u001b[0m\u001b[0m\n\u001b[1;32m      3\u001b[0m \u001b[0mspark\u001b[0m \u001b[0;34m=\u001b[0m \u001b[0mSparkSession\u001b[0m\u001b[0;34m.\u001b[0m\u001b[0mbuilder\u001b[0m\u001b[0;34m.\u001b[0m\u001b[0mgetOrCreate\u001b[0m\u001b[0;34m(\u001b[0m\u001b[0;34m)\u001b[0m\u001b[0;34m\u001b[0m\u001b[0;34m\u001b[0m\u001b[0m\n\u001b[0;32m----> 4\u001b[0;31m \u001b[0mratingsDF\u001b[0m \u001b[0;34m=\u001b[0m \u001b[0mspark\u001b[0m\u001b[0;34m.\u001b[0m\u001b[0mread\u001b[0m\u001b[0;34m.\u001b[0m\u001b[0moptions\u001b[0m\u001b[0;34m(\u001b[0m\u001b[0mheader\u001b[0m\u001b[0;34m=\u001b[0m\u001b[0;34m'True'\u001b[0m\u001b[0;34m,\u001b[0m \u001b[0minferSchema\u001b[0m\u001b[0;34m=\u001b[0m\u001b[0;34m'True'\u001b[0m\u001b[0;34m,\u001b[0m \u001b[0mdelimiter\u001b[0m\u001b[0;34m=\u001b[0m\u001b[0;34m','\u001b[0m\u001b[0;34m)\u001b[0m\u001b[0;34m.\u001b[0m\u001b[0mcsv\u001b[0m\u001b[0;34m(\u001b[0m\u001b[0;34m\"/content/gdrive/MyDrive/Bigdata-Pyspark-Dataset/Assignment2/ratings_small.csv\"\u001b[0m\u001b[0;34m)\u001b[0m\u001b[0;34m\u001b[0m\u001b[0;34m\u001b[0m\u001b[0m\n\u001b[0m\u001b[1;32m      5\u001b[0m \u001b[0mmoviesDF\u001b[0m \u001b[0;34m=\u001b[0m \u001b[0mspark\u001b[0m\u001b[0;34m.\u001b[0m\u001b[0mread\u001b[0m\u001b[0;34m.\u001b[0m\u001b[0moptions\u001b[0m\u001b[0;34m(\u001b[0m\u001b[0mheader\u001b[0m\u001b[0;34m=\u001b[0m\u001b[0;34m'True'\u001b[0m\u001b[0;34m,\u001b[0m \u001b[0minferSchema\u001b[0m\u001b[0;34m=\u001b[0m\u001b[0;34m'True'\u001b[0m\u001b[0;34m,\u001b[0m \u001b[0mdelimiter\u001b[0m\u001b[0;34m=\u001b[0m\u001b[0;34m','\u001b[0m\u001b[0;34m)\u001b[0m\u001b[0;34m.\u001b[0m\u001b[0mcsv\u001b[0m\u001b[0;34m(\u001b[0m\u001b[0;34m\"/content/gdrive/MyDrive/Bigdata-Pyspark-Dataset/Assignment2/movies_small.csv\"\u001b[0m\u001b[0;34m)\u001b[0m\u001b[0;34m\u001b[0m\u001b[0;34m\u001b[0m\u001b[0m\n",
            "\u001b[0;32m/usr/local/lib/python3.10/dist-packages/pyspark/sql/session.py\u001b[0m in \u001b[0;36mread\u001b[0;34m(self)\u001b[0m\n\u001b[1;32m    671\u001b[0m         \u001b[0;34m:\u001b[0m\u001b[0;32mreturn\u001b[0m\u001b[0;34m:\u001b[0m \u001b[0;34m:\u001b[0m\u001b[0;32mclass\u001b[0m\u001b[0;34m:\u001b[0m\u001b[0;31m`\u001b[0m\u001b[0mDataFrameReader\u001b[0m\u001b[0;31m`\u001b[0m\u001b[0;34m\u001b[0m\u001b[0;34m\u001b[0m\u001b[0m\n\u001b[1;32m    672\u001b[0m         \"\"\"\n\u001b[0;32m--> 673\u001b[0;31m         \u001b[0;32mreturn\u001b[0m \u001b[0mDataFrameReader\u001b[0m\u001b[0;34m(\u001b[0m\u001b[0mself\u001b[0m\u001b[0;34m.\u001b[0m\u001b[0m_wrapped\u001b[0m\u001b[0;34m)\u001b[0m\u001b[0;34m\u001b[0m\u001b[0;34m\u001b[0m\u001b[0m\n\u001b[0m\u001b[1;32m    674\u001b[0m \u001b[0;34m\u001b[0m\u001b[0m\n\u001b[1;32m    675\u001b[0m     \u001b[0;34m@\u001b[0m\u001b[0mproperty\u001b[0m\u001b[0;34m\u001b[0m\u001b[0;34m\u001b[0m\u001b[0m\n",
            "\u001b[0;32m/usr/local/lib/python3.10/dist-packages/pyspark/sql/readwriter.py\u001b[0m in \u001b[0;36m__init__\u001b[0;34m(self, spark)\u001b[0m\n\u001b[1;32m     56\u001b[0m \u001b[0;34m\u001b[0m\u001b[0m\n\u001b[1;32m     57\u001b[0m     \u001b[0;32mdef\u001b[0m \u001b[0m__init__\u001b[0m\u001b[0;34m(\u001b[0m\u001b[0mself\u001b[0m\u001b[0;34m,\u001b[0m \u001b[0mspark\u001b[0m\u001b[0;34m)\u001b[0m\u001b[0;34m:\u001b[0m\u001b[0;34m\u001b[0m\u001b[0;34m\u001b[0m\u001b[0m\n\u001b[0;32m---> 58\u001b[0;31m         \u001b[0mself\u001b[0m\u001b[0;34m.\u001b[0m\u001b[0m_jreader\u001b[0m \u001b[0;34m=\u001b[0m \u001b[0mspark\u001b[0m\u001b[0;34m.\u001b[0m\u001b[0m_ssql_ctx\u001b[0m\u001b[0;34m.\u001b[0m\u001b[0mread\u001b[0m\u001b[0;34m(\u001b[0m\u001b[0;34m)\u001b[0m\u001b[0;34m\u001b[0m\u001b[0;34m\u001b[0m\u001b[0m\n\u001b[0m\u001b[1;32m     59\u001b[0m         \u001b[0mself\u001b[0m\u001b[0;34m.\u001b[0m\u001b[0m_spark\u001b[0m \u001b[0;34m=\u001b[0m \u001b[0mspark\u001b[0m\u001b[0;34m\u001b[0m\u001b[0;34m\u001b[0m\u001b[0m\n\u001b[1;32m     60\u001b[0m \u001b[0;34m\u001b[0m\u001b[0m\n",
            "\u001b[0;32m/usr/local/lib/python3.10/dist-packages/py4j/java_gateway.py\u001b[0m in \u001b[0;36m__call__\u001b[0;34m(self, *args)\u001b[0m\n\u001b[1;32m   1301\u001b[0m             \u001b[0mproto\u001b[0m\u001b[0;34m.\u001b[0m\u001b[0mEND_COMMAND_PART\u001b[0m\u001b[0;34m\u001b[0m\u001b[0;34m\u001b[0m\u001b[0m\n\u001b[1;32m   1302\u001b[0m \u001b[0;34m\u001b[0m\u001b[0m\n\u001b[0;32m-> 1303\u001b[0;31m         \u001b[0manswer\u001b[0m \u001b[0;34m=\u001b[0m \u001b[0mself\u001b[0m\u001b[0;34m.\u001b[0m\u001b[0mgateway_client\u001b[0m\u001b[0;34m.\u001b[0m\u001b[0msend_command\u001b[0m\u001b[0;34m(\u001b[0m\u001b[0mcommand\u001b[0m\u001b[0;34m)\u001b[0m\u001b[0;34m\u001b[0m\u001b[0;34m\u001b[0m\u001b[0m\n\u001b[0m\u001b[1;32m   1304\u001b[0m         return_value = get_return_value(\n\u001b[1;32m   1305\u001b[0m             answer, self.gateway_client, self.target_id, self.name)\n",
            "\u001b[0;32m/usr/local/lib/python3.10/dist-packages/py4j/java_gateway.py\u001b[0m in \u001b[0;36msend_command\u001b[0;34m(self, command, retry, binary)\u001b[0m\n\u001b[1;32m   1029\u001b[0m          \u001b[0;32mif\u001b[0m\u001b[0;31m \u001b[0m\u001b[0;31m`\u001b[0m\u001b[0mbinary\u001b[0m\u001b[0;31m`\u001b[0m \u001b[0;32mis\u001b[0m\u001b[0;31m \u001b[0m\u001b[0;31m`\u001b[0m\u001b[0;32mTrue\u001b[0m\u001b[0;31m`\u001b[0m\u001b[0;34m.\u001b[0m\u001b[0;34m\u001b[0m\u001b[0;34m\u001b[0m\u001b[0m\n\u001b[1;32m   1030\u001b[0m         \"\"\"\n\u001b[0;32m-> 1031\u001b[0;31m         \u001b[0mconnection\u001b[0m \u001b[0;34m=\u001b[0m \u001b[0mself\u001b[0m\u001b[0;34m.\u001b[0m\u001b[0m_get_connection\u001b[0m\u001b[0;34m(\u001b[0m\u001b[0;34m)\u001b[0m\u001b[0;34m\u001b[0m\u001b[0;34m\u001b[0m\u001b[0m\n\u001b[0m\u001b[1;32m   1032\u001b[0m         \u001b[0;32mtry\u001b[0m\u001b[0;34m:\u001b[0m\u001b[0;34m\u001b[0m\u001b[0;34m\u001b[0m\u001b[0m\n\u001b[1;32m   1033\u001b[0m             \u001b[0mresponse\u001b[0m \u001b[0;34m=\u001b[0m \u001b[0mconnection\u001b[0m\u001b[0;34m.\u001b[0m\u001b[0msend_command\u001b[0m\u001b[0;34m(\u001b[0m\u001b[0mcommand\u001b[0m\u001b[0;34m)\u001b[0m\u001b[0;34m\u001b[0m\u001b[0;34m\u001b[0m\u001b[0m\n",
            "\u001b[0;32m/usr/local/lib/python3.10/dist-packages/py4j/java_gateway.py\u001b[0m in \u001b[0;36m_get_connection\u001b[0;34m(self)\u001b[0m\n\u001b[1;32m    977\u001b[0m             \u001b[0mconnection\u001b[0m \u001b[0;34m=\u001b[0m \u001b[0mself\u001b[0m\u001b[0;34m.\u001b[0m\u001b[0mdeque\u001b[0m\u001b[0;34m.\u001b[0m\u001b[0mpop\u001b[0m\u001b[0;34m(\u001b[0m\u001b[0;34m)\u001b[0m\u001b[0;34m\u001b[0m\u001b[0;34m\u001b[0m\u001b[0m\n\u001b[1;32m    978\u001b[0m         \u001b[0;32mexcept\u001b[0m \u001b[0mIndexError\u001b[0m\u001b[0;34m:\u001b[0m\u001b[0;34m\u001b[0m\u001b[0;34m\u001b[0m\u001b[0m\n\u001b[0;32m--> 979\u001b[0;31m             \u001b[0mconnection\u001b[0m \u001b[0;34m=\u001b[0m \u001b[0mself\u001b[0m\u001b[0;34m.\u001b[0m\u001b[0m_create_connection\u001b[0m\u001b[0;34m(\u001b[0m\u001b[0;34m)\u001b[0m\u001b[0;34m\u001b[0m\u001b[0;34m\u001b[0m\u001b[0m\n\u001b[0m\u001b[1;32m    980\u001b[0m         \u001b[0;32mreturn\u001b[0m \u001b[0mconnection\u001b[0m\u001b[0;34m\u001b[0m\u001b[0;34m\u001b[0m\u001b[0m\n\u001b[1;32m    981\u001b[0m \u001b[0;34m\u001b[0m\u001b[0m\n",
            "\u001b[0;32m/usr/local/lib/python3.10/dist-packages/py4j/java_gateway.py\u001b[0m in \u001b[0;36m_create_connection\u001b[0;34m(self)\u001b[0m\n\u001b[1;32m    983\u001b[0m         connection = GatewayConnection(\n\u001b[1;32m    984\u001b[0m             self.gateway_parameters, self.gateway_property)\n\u001b[0;32m--> 985\u001b[0;31m         \u001b[0mconnection\u001b[0m\u001b[0;34m.\u001b[0m\u001b[0mstart\u001b[0m\u001b[0;34m(\u001b[0m\u001b[0;34m)\u001b[0m\u001b[0;34m\u001b[0m\u001b[0;34m\u001b[0m\u001b[0m\n\u001b[0m\u001b[1;32m    986\u001b[0m         \u001b[0;32mreturn\u001b[0m \u001b[0mconnection\u001b[0m\u001b[0;34m\u001b[0m\u001b[0;34m\u001b[0m\u001b[0m\n\u001b[1;32m    987\u001b[0m \u001b[0;34m\u001b[0m\u001b[0m\n",
            "\u001b[0;32m/usr/local/lib/python3.10/dist-packages/py4j/java_gateway.py\u001b[0m in \u001b[0;36mstart\u001b[0;34m(self)\u001b[0m\n\u001b[1;32m   1125\u001b[0m                 \u001b[0;34m\"server ({0}:{1})\"\u001b[0m\u001b[0;34m.\u001b[0m\u001b[0mformat\u001b[0m\u001b[0;34m(\u001b[0m\u001b[0mself\u001b[0m\u001b[0;34m.\u001b[0m\u001b[0maddress\u001b[0m\u001b[0;34m,\u001b[0m \u001b[0mself\u001b[0m\u001b[0;34m.\u001b[0m\u001b[0mport\u001b[0m\u001b[0;34m)\u001b[0m\u001b[0;34m\u001b[0m\u001b[0;34m\u001b[0m\u001b[0m\n\u001b[1;32m   1126\u001b[0m             \u001b[0mlogger\u001b[0m\u001b[0;34m.\u001b[0m\u001b[0mexception\u001b[0m\u001b[0;34m(\u001b[0m\u001b[0mmsg\u001b[0m\u001b[0;34m)\u001b[0m\u001b[0;34m\u001b[0m\u001b[0;34m\u001b[0m\u001b[0m\n\u001b[0;32m-> 1127\u001b[0;31m             \u001b[0;32mraise\u001b[0m \u001b[0mPy4JNetworkError\u001b[0m\u001b[0;34m(\u001b[0m\u001b[0mmsg\u001b[0m\u001b[0;34m,\u001b[0m \u001b[0me\u001b[0m\u001b[0;34m)\u001b[0m\u001b[0;34m\u001b[0m\u001b[0;34m\u001b[0m\u001b[0m\n\u001b[0m\u001b[1;32m   1128\u001b[0m \u001b[0;34m\u001b[0m\u001b[0m\n\u001b[1;32m   1129\u001b[0m     \u001b[0;32mdef\u001b[0m \u001b[0m_authenticate_connection\u001b[0m\u001b[0;34m(\u001b[0m\u001b[0mself\u001b[0m\u001b[0;34m)\u001b[0m\u001b[0;34m:\u001b[0m\u001b[0;34m\u001b[0m\u001b[0;34m\u001b[0m\u001b[0m\n",
            "\u001b[0;31mPy4JNetworkError\u001b[0m: An error occurred while trying to connect to the Java server (127.0.0.1:42473)"
          ]
        }
      ]
    },
    {
      "cell_type": "code",
      "source": [
        "moviesDF = moviesDF.withColumn(\"genres\",f.explode(f.split(\"genres\", \"\\\\|\")))\n",
        "moviesDF.show()"
      ],
      "metadata": {
        "id": "AtMImDXvducj",
        "colab": {
          "base_uri": "https://localhost:8080/"
        },
        "outputId": "deae31e7-ab85-4e51-c1ab-602e43d4371d"
      },
      "execution_count": 4,
      "outputs": [
        {
          "output_type": "stream",
          "name": "stdout",
          "text": [
            "+-------+--------------------+---------+\n",
            "|movieId|               title|   genres|\n",
            "+-------+--------------------+---------+\n",
            "|      1|    Toy Story (1995)|Adventure|\n",
            "|      1|    Toy Story (1995)|Animation|\n",
            "|      1|    Toy Story (1995)| Children|\n",
            "|      1|    Toy Story (1995)|   Comedy|\n",
            "|      1|    Toy Story (1995)|  Fantasy|\n",
            "|      2|      Jumanji (1995)|Adventure|\n",
            "|      2|      Jumanji (1995)| Children|\n",
            "|      2|      Jumanji (1995)|  Fantasy|\n",
            "|      3|Grumpier Old Men ...|   Comedy|\n",
            "|      3|Grumpier Old Men ...|  Romance|\n",
            "|      4|Waiting to Exhale...|   Comedy|\n",
            "|      4|Waiting to Exhale...|    Drama|\n",
            "|      4|Waiting to Exhale...|  Romance|\n",
            "|      5|Father of the Bri...|   Comedy|\n",
            "|      6|         Heat (1995)|   Action|\n",
            "|      6|         Heat (1995)|    Crime|\n",
            "|      6|         Heat (1995)| Thriller|\n",
            "|      7|      Sabrina (1995)|   Comedy|\n",
            "|      7|      Sabrina (1995)|  Romance|\n",
            "|      8| Tom and Huck (1995)|Adventure|\n",
            "+-------+--------------------+---------+\n",
            "only showing top 20 rows\n",
            "\n"
          ]
        }
      ]
    },
    {
      "cell_type": "code",
      "source": [
        "from pyspark.sql import functions as f\n",
        "from pyspark.sql.window import Window\n",
        "from pyspark.sql.types import ArrayType, FloatType\n",
        "\n",
        "\n",
        "# Step 1: Calculate average rating by genre and by movieId\n",
        "genre_ratings = ratingsDF.join(moviesDF, on='movieId', how='inner').groupBy('genres') \\\n",
        "    .agg(f.avg('rating').alias('genre_avg_rating'), f.collect_list('movieId').alias('genre_movies'))\n",
        "\n",
        "movie_ratings = ratingsDF.groupBy('movieId').agg(f.avg('rating').alias('movie_avg_rating'))\n",
        "\n",
        "# Step 2: Find highest rated genre for each user\n",
        "user_highest_rated_genre = ratingsDF.join(moviesDF, on='movieId', how='inner').groupBy('userId', 'genres') \\\n",
        "    .agg(f.avg('rating').alias('user_genre_avg_rating')) \\\n",
        "    .withColumn('rank', f.rank().over(Window.partitionBy('userId').orderBy(f.desc('user_genre_avg_rating')))) \\\n",
        "    .where(f.col('rank') == 1) \\\n",
        "    .select('userId', 'genres', 'user_genre_avg_rating')\n",
        "\n",
        "# Step 3: Find top 5 unrated movies with highest rating for each highest rated genre\n",
        "# Create a DataFrame containing 'movieId' and 'genres'\n",
        "movies_id_genre = ratingsDF.join(moviesDF, on='movieId', how='inner').select('movieId', 'genres')\n",
        "\n",
        "# Join 'movie_ratings' with DataFrame to get access to 'movie_avg_rating'\n",
        "unrated_movies_with_ratings = movies_id_genre.join(movie_ratings, on='movieId', how='inner')\n",
        "\n",
        "# Define a UDF to extract values from an array column\n",
        "extract_rating_udf = f.udf(lambda arr: [item['rating'] for item in arr], ArrayType(FloatType()))\n",
        "\n",
        "# Calculate the top 5 unrated movies for each user and genre\n",
        "top_unrated_movies = user_highest_rated_genre.join(genre_ratings, on='genres', how='inner') \\\n",
        "    .join(unrated_movies_with_ratings, on='genres', how='inner') \\\n",
        "    .withColumn('unrated_movies', f.array_except('genre_movies', f.collect_list('movieId').over(Window.partitionBy('userId')))) \\\n",
        "    .withColumn('unrated_movie_avg_rating', extract_rating_udf('unrated_movies')) \\\n",
        "    .withColumn('top_5_unrated_movies', f.explode(f.arrays_zip(f.col('unrated_movies'), f.col('unrated_movie_avg_rating')))) \\\n",
        "    .select('userId', 'genres', 'genre_avg_rating', 'top_5_unrated_movies.*') \\\n",
        "    .orderBy('userId', 'genres', f.desc('unrated_movie_avg_rating')) \\\n",
        "    .groupBy('userId', 'genres', 'genre_avg_rating') \\\n",
        "    .agg(f.collect_list(f.struct('unrated_movies', 'unrated_movie_avg_rating')).alias('top_5_unrated_movies'))"
      ],
      "metadata": {
        "id": "QNyzc60wdvQz"
      },
      "execution_count": 5,
      "outputs": []
    },
    {
      "cell_type": "code",
      "source": [
        "top_unrated_movies.show(100)\n"
      ],
      "metadata": {
        "colab": {
          "base_uri": "https://localhost:8080/",
          "height": 727
        },
        "id": "mGrDq2dbfAM2",
        "outputId": "f00127de-dcd4-4330-a625-e42218ec9cfd"
      },
      "execution_count": 8,
      "outputs": [
        {
          "output_type": "stream",
          "name": "stderr",
          "text": [
            "ERROR:py4j.java_gateway:An error occurred while trying to connect to the Java server (127.0.0.1:42473)\n",
            "Traceback (most recent call last):\n",
            "  File \"/usr/local/lib/python3.10/dist-packages/py4j/java_gateway.py\", line 977, in _get_connection\n",
            "    connection = self.deque.pop()\n",
            "IndexError: pop from an empty deque\n",
            "\n",
            "During handling of the above exception, another exception occurred:\n",
            "\n",
            "Traceback (most recent call last):\n",
            "  File \"/usr/local/lib/python3.10/dist-packages/py4j/java_gateway.py\", line 1115, in start\n",
            "    self.socket.connect((self.address, self.port))\n",
            "ConnectionRefusedError: [Errno 111] Connection refused\n"
          ]
        },
        {
          "output_type": "error",
          "ename": "Py4JNetworkError",
          "evalue": "ignored",
          "traceback": [
            "\u001b[0;31m---------------------------------------------------------------------------\u001b[0m",
            "\u001b[0;31mIndexError\u001b[0m                                Traceback (most recent call last)",
            "\u001b[0;32m/usr/local/lib/python3.10/dist-packages/py4j/java_gateway.py\u001b[0m in \u001b[0;36m_get_connection\u001b[0;34m(self)\u001b[0m\n\u001b[1;32m    976\u001b[0m         \u001b[0;32mtry\u001b[0m\u001b[0;34m:\u001b[0m\u001b[0;34m\u001b[0m\u001b[0;34m\u001b[0m\u001b[0m\n\u001b[0;32m--> 977\u001b[0;31m             \u001b[0mconnection\u001b[0m \u001b[0;34m=\u001b[0m \u001b[0mself\u001b[0m\u001b[0;34m.\u001b[0m\u001b[0mdeque\u001b[0m\u001b[0;34m.\u001b[0m\u001b[0mpop\u001b[0m\u001b[0;34m(\u001b[0m\u001b[0;34m)\u001b[0m\u001b[0;34m\u001b[0m\u001b[0;34m\u001b[0m\u001b[0m\n\u001b[0m\u001b[1;32m    978\u001b[0m         \u001b[0;32mexcept\u001b[0m \u001b[0mIndexError\u001b[0m\u001b[0;34m:\u001b[0m\u001b[0;34m\u001b[0m\u001b[0;34m\u001b[0m\u001b[0m\n",
            "\u001b[0;31mIndexError\u001b[0m: pop from an empty deque",
            "\nDuring handling of the above exception, another exception occurred:\n",
            "\u001b[0;31mConnectionRefusedError\u001b[0m                    Traceback (most recent call last)",
            "\u001b[0;32m/usr/local/lib/python3.10/dist-packages/py4j/java_gateway.py\u001b[0m in \u001b[0;36mstart\u001b[0;34m(self)\u001b[0m\n\u001b[1;32m   1114\u001b[0m         \u001b[0;32mtry\u001b[0m\u001b[0;34m:\u001b[0m\u001b[0;34m\u001b[0m\u001b[0;34m\u001b[0m\u001b[0m\n\u001b[0;32m-> 1115\u001b[0;31m             \u001b[0mself\u001b[0m\u001b[0;34m.\u001b[0m\u001b[0msocket\u001b[0m\u001b[0;34m.\u001b[0m\u001b[0mconnect\u001b[0m\u001b[0;34m(\u001b[0m\u001b[0;34m(\u001b[0m\u001b[0mself\u001b[0m\u001b[0;34m.\u001b[0m\u001b[0maddress\u001b[0m\u001b[0;34m,\u001b[0m \u001b[0mself\u001b[0m\u001b[0;34m.\u001b[0m\u001b[0mport\u001b[0m\u001b[0;34m)\u001b[0m\u001b[0;34m)\u001b[0m\u001b[0;34m\u001b[0m\u001b[0;34m\u001b[0m\u001b[0m\n\u001b[0m\u001b[1;32m   1116\u001b[0m             \u001b[0mself\u001b[0m\u001b[0;34m.\u001b[0m\u001b[0mstream\u001b[0m \u001b[0;34m=\u001b[0m \u001b[0mself\u001b[0m\u001b[0;34m.\u001b[0m\u001b[0msocket\u001b[0m\u001b[0;34m.\u001b[0m\u001b[0mmakefile\u001b[0m\u001b[0;34m(\u001b[0m\u001b[0;34m\"rb\"\u001b[0m\u001b[0;34m)\u001b[0m\u001b[0;34m\u001b[0m\u001b[0;34m\u001b[0m\u001b[0m\n",
            "\u001b[0;31mConnectionRefusedError\u001b[0m: [Errno 111] Connection refused",
            "\nDuring handling of the above exception, another exception occurred:\n",
            "\u001b[0;31mPy4JNetworkError\u001b[0m                          Traceback (most recent call last)",
            "\u001b[0;32m<ipython-input-8-69a9c8ab67ff>\u001b[0m in \u001b[0;36m<cell line: 1>\u001b[0;34m()\u001b[0m\n\u001b[0;32m----> 1\u001b[0;31m \u001b[0mtop_unrated_movies\u001b[0m\u001b[0;34m.\u001b[0m\u001b[0mshow\u001b[0m\u001b[0;34m(\u001b[0m\u001b[0;36m100\u001b[0m\u001b[0;34m)\u001b[0m\u001b[0;34m\u001b[0m\u001b[0;34m\u001b[0m\u001b[0m\n\u001b[0m",
            "\u001b[0;32m/usr/local/lib/python3.10/dist-packages/pyspark/sql/dataframe.py\u001b[0m in \u001b[0;36mshow\u001b[0;34m(self, n, truncate, vertical)\u001b[0m\n\u001b[1;32m    438\u001b[0m         \"\"\"\n\u001b[1;32m    439\u001b[0m         \u001b[0;32mif\u001b[0m \u001b[0misinstance\u001b[0m\u001b[0;34m(\u001b[0m\u001b[0mtruncate\u001b[0m\u001b[0;34m,\u001b[0m \u001b[0mbool\u001b[0m\u001b[0;34m)\u001b[0m \u001b[0;32mand\u001b[0m \u001b[0mtruncate\u001b[0m\u001b[0;34m:\u001b[0m\u001b[0;34m\u001b[0m\u001b[0;34m\u001b[0m\u001b[0m\n\u001b[0;32m--> 440\u001b[0;31m             \u001b[0mprint\u001b[0m\u001b[0;34m(\u001b[0m\u001b[0mself\u001b[0m\u001b[0;34m.\u001b[0m\u001b[0m_jdf\u001b[0m\u001b[0;34m.\u001b[0m\u001b[0mshowString\u001b[0m\u001b[0;34m(\u001b[0m\u001b[0mn\u001b[0m\u001b[0;34m,\u001b[0m \u001b[0;36m20\u001b[0m\u001b[0;34m,\u001b[0m \u001b[0mvertical\u001b[0m\u001b[0;34m)\u001b[0m\u001b[0;34m)\u001b[0m\u001b[0;34m\u001b[0m\u001b[0;34m\u001b[0m\u001b[0m\n\u001b[0m\u001b[1;32m    441\u001b[0m         \u001b[0;32melse\u001b[0m\u001b[0;34m:\u001b[0m\u001b[0;34m\u001b[0m\u001b[0;34m\u001b[0m\u001b[0m\n\u001b[1;32m    442\u001b[0m             \u001b[0mprint\u001b[0m\u001b[0;34m(\u001b[0m\u001b[0mself\u001b[0m\u001b[0;34m.\u001b[0m\u001b[0m_jdf\u001b[0m\u001b[0;34m.\u001b[0m\u001b[0mshowString\u001b[0m\u001b[0;34m(\u001b[0m\u001b[0mn\u001b[0m\u001b[0;34m,\u001b[0m \u001b[0mint\u001b[0m\u001b[0;34m(\u001b[0m\u001b[0mtruncate\u001b[0m\u001b[0;34m)\u001b[0m\u001b[0;34m,\u001b[0m \u001b[0mvertical\u001b[0m\u001b[0;34m)\u001b[0m\u001b[0;34m)\u001b[0m\u001b[0;34m\u001b[0m\u001b[0;34m\u001b[0m\u001b[0m\n",
            "\u001b[0;32m/usr/local/lib/python3.10/dist-packages/py4j/java_gateway.py\u001b[0m in \u001b[0;36m__call__\u001b[0;34m(self, *args)\u001b[0m\n\u001b[1;32m   1301\u001b[0m             \u001b[0mproto\u001b[0m\u001b[0;34m.\u001b[0m\u001b[0mEND_COMMAND_PART\u001b[0m\u001b[0;34m\u001b[0m\u001b[0;34m\u001b[0m\u001b[0m\n\u001b[1;32m   1302\u001b[0m \u001b[0;34m\u001b[0m\u001b[0m\n\u001b[0;32m-> 1303\u001b[0;31m         \u001b[0manswer\u001b[0m \u001b[0;34m=\u001b[0m \u001b[0mself\u001b[0m\u001b[0;34m.\u001b[0m\u001b[0mgateway_client\u001b[0m\u001b[0;34m.\u001b[0m\u001b[0msend_command\u001b[0m\u001b[0;34m(\u001b[0m\u001b[0mcommand\u001b[0m\u001b[0;34m)\u001b[0m\u001b[0;34m\u001b[0m\u001b[0;34m\u001b[0m\u001b[0m\n\u001b[0m\u001b[1;32m   1304\u001b[0m         return_value = get_return_value(\n\u001b[1;32m   1305\u001b[0m             answer, self.gateway_client, self.target_id, self.name)\n",
            "\u001b[0;32m/usr/local/lib/python3.10/dist-packages/py4j/java_gateway.py\u001b[0m in \u001b[0;36msend_command\u001b[0;34m(self, command, retry, binary)\u001b[0m\n\u001b[1;32m   1029\u001b[0m          \u001b[0;32mif\u001b[0m\u001b[0;31m \u001b[0m\u001b[0;31m`\u001b[0m\u001b[0mbinary\u001b[0m\u001b[0;31m`\u001b[0m \u001b[0;32mis\u001b[0m\u001b[0;31m \u001b[0m\u001b[0;31m`\u001b[0m\u001b[0;32mTrue\u001b[0m\u001b[0;31m`\u001b[0m\u001b[0;34m.\u001b[0m\u001b[0;34m\u001b[0m\u001b[0;34m\u001b[0m\u001b[0m\n\u001b[1;32m   1030\u001b[0m         \"\"\"\n\u001b[0;32m-> 1031\u001b[0;31m         \u001b[0mconnection\u001b[0m \u001b[0;34m=\u001b[0m \u001b[0mself\u001b[0m\u001b[0;34m.\u001b[0m\u001b[0m_get_connection\u001b[0m\u001b[0;34m(\u001b[0m\u001b[0;34m)\u001b[0m\u001b[0;34m\u001b[0m\u001b[0;34m\u001b[0m\u001b[0m\n\u001b[0m\u001b[1;32m   1032\u001b[0m         \u001b[0;32mtry\u001b[0m\u001b[0;34m:\u001b[0m\u001b[0;34m\u001b[0m\u001b[0;34m\u001b[0m\u001b[0m\n\u001b[1;32m   1033\u001b[0m             \u001b[0mresponse\u001b[0m \u001b[0;34m=\u001b[0m \u001b[0mconnection\u001b[0m\u001b[0;34m.\u001b[0m\u001b[0msend_command\u001b[0m\u001b[0;34m(\u001b[0m\u001b[0mcommand\u001b[0m\u001b[0;34m)\u001b[0m\u001b[0;34m\u001b[0m\u001b[0;34m\u001b[0m\u001b[0m\n",
            "\u001b[0;32m/usr/local/lib/python3.10/dist-packages/py4j/java_gateway.py\u001b[0m in \u001b[0;36m_get_connection\u001b[0;34m(self)\u001b[0m\n\u001b[1;32m    977\u001b[0m             \u001b[0mconnection\u001b[0m \u001b[0;34m=\u001b[0m \u001b[0mself\u001b[0m\u001b[0;34m.\u001b[0m\u001b[0mdeque\u001b[0m\u001b[0;34m.\u001b[0m\u001b[0mpop\u001b[0m\u001b[0;34m(\u001b[0m\u001b[0;34m)\u001b[0m\u001b[0;34m\u001b[0m\u001b[0;34m\u001b[0m\u001b[0m\n\u001b[1;32m    978\u001b[0m         \u001b[0;32mexcept\u001b[0m \u001b[0mIndexError\u001b[0m\u001b[0;34m:\u001b[0m\u001b[0;34m\u001b[0m\u001b[0;34m\u001b[0m\u001b[0m\n\u001b[0;32m--> 979\u001b[0;31m             \u001b[0mconnection\u001b[0m \u001b[0;34m=\u001b[0m \u001b[0mself\u001b[0m\u001b[0;34m.\u001b[0m\u001b[0m_create_connection\u001b[0m\u001b[0;34m(\u001b[0m\u001b[0;34m)\u001b[0m\u001b[0;34m\u001b[0m\u001b[0;34m\u001b[0m\u001b[0m\n\u001b[0m\u001b[1;32m    980\u001b[0m         \u001b[0;32mreturn\u001b[0m \u001b[0mconnection\u001b[0m\u001b[0;34m\u001b[0m\u001b[0;34m\u001b[0m\u001b[0m\n\u001b[1;32m    981\u001b[0m \u001b[0;34m\u001b[0m\u001b[0m\n",
            "\u001b[0;32m/usr/local/lib/python3.10/dist-packages/py4j/java_gateway.py\u001b[0m in \u001b[0;36m_create_connection\u001b[0;34m(self)\u001b[0m\n\u001b[1;32m    983\u001b[0m         connection = GatewayConnection(\n\u001b[1;32m    984\u001b[0m             self.gateway_parameters, self.gateway_property)\n\u001b[0;32m--> 985\u001b[0;31m         \u001b[0mconnection\u001b[0m\u001b[0;34m.\u001b[0m\u001b[0mstart\u001b[0m\u001b[0;34m(\u001b[0m\u001b[0;34m)\u001b[0m\u001b[0;34m\u001b[0m\u001b[0;34m\u001b[0m\u001b[0m\n\u001b[0m\u001b[1;32m    986\u001b[0m         \u001b[0;32mreturn\u001b[0m \u001b[0mconnection\u001b[0m\u001b[0;34m\u001b[0m\u001b[0;34m\u001b[0m\u001b[0m\n\u001b[1;32m    987\u001b[0m \u001b[0;34m\u001b[0m\u001b[0m\n",
            "\u001b[0;32m/usr/local/lib/python3.10/dist-packages/py4j/java_gateway.py\u001b[0m in \u001b[0;36mstart\u001b[0;34m(self)\u001b[0m\n\u001b[1;32m   1125\u001b[0m                 \u001b[0;34m\"server ({0}:{1})\"\u001b[0m\u001b[0;34m.\u001b[0m\u001b[0mformat\u001b[0m\u001b[0;34m(\u001b[0m\u001b[0mself\u001b[0m\u001b[0;34m.\u001b[0m\u001b[0maddress\u001b[0m\u001b[0;34m,\u001b[0m \u001b[0mself\u001b[0m\u001b[0;34m.\u001b[0m\u001b[0mport\u001b[0m\u001b[0;34m)\u001b[0m\u001b[0;34m\u001b[0m\u001b[0;34m\u001b[0m\u001b[0m\n\u001b[1;32m   1126\u001b[0m             \u001b[0mlogger\u001b[0m\u001b[0;34m.\u001b[0m\u001b[0mexception\u001b[0m\u001b[0;34m(\u001b[0m\u001b[0mmsg\u001b[0m\u001b[0;34m)\u001b[0m\u001b[0;34m\u001b[0m\u001b[0;34m\u001b[0m\u001b[0m\n\u001b[0;32m-> 1127\u001b[0;31m             \u001b[0;32mraise\u001b[0m \u001b[0mPy4JNetworkError\u001b[0m\u001b[0;34m(\u001b[0m\u001b[0mmsg\u001b[0m\u001b[0;34m,\u001b[0m \u001b[0me\u001b[0m\u001b[0;34m)\u001b[0m\u001b[0;34m\u001b[0m\u001b[0;34m\u001b[0m\u001b[0m\n\u001b[0m\u001b[1;32m   1128\u001b[0m \u001b[0;34m\u001b[0m\u001b[0m\n\u001b[1;32m   1129\u001b[0m     \u001b[0;32mdef\u001b[0m \u001b[0m_authenticate_connection\u001b[0m\u001b[0;34m(\u001b[0m\u001b[0mself\u001b[0m\u001b[0;34m)\u001b[0m\u001b[0;34m:\u001b[0m\u001b[0;34m\u001b[0m\u001b[0;34m\u001b[0m\u001b[0m\n",
            "\u001b[0;31mPy4JNetworkError\u001b[0m: An error occurred while trying to connect to the Java server (127.0.0.1:42473)"
          ]
        }
      ]
    },
    {
      "cell_type": "code",
      "source": [],
      "metadata": {
        "id": "bWK0wUnlgAes"
      },
      "execution_count": null,
      "outputs": []
    }
  ]
}